[] Section14
- [] #Chapter 46 Different Strategies/Options to handle Exceptions in CompletableFuture
{Revise}
- [] #Chapter 47 Handle/Recover Exception using "handle" function
  - [Run Test] com.gauro.demo.completablefuture.CompletableFutureHelloWorldExceptionTest.helloWorld_3_async_calls_handle
  
- [] #Chapter 48 Handle/Recover Exception using "handle" function-part2
  - [Run Test] com.gauro.demo.completablefuture.CompletableFutureHelloWorldExceptionTest.helloWorld_3_async_calls_handle_2
  
- [] #Chapter 49 Handle/Recover Exception using "Handle" function-part3
  - [Run Test] com.gauro.demo.completablefuture.CompletableFutureHelloWorldExceptionTest.helloWorld_3_async_calls_handle_3

- [] #Chapter 50 Handle/Recover Exception using "exceptionally" function
  - [Run Test] com.gauro.demo.completablefuture.CompletableFutureHelloWorldExceptionTest.helloWorld_3_async_call_exceptionally
  
- [] #Chapter 51 Handle Exception using "whenComplete" function
  {revise}
  
  - [Run Test] com.gauro.demo.completablefuture.CompletableFutureHelloWorldExceptionTest.helloWorld_3_async_calls_whenhandle
